<?xml version="1.0" encoding="UTF-8"?>
<!-- Generated by org.testng.reporters.JUnitReportReporter -->
<testsuite name="file.FileUtilTest" tests="6" time="0.031" ignored="6" failures="0" timestamp="07 二月 2017 02:51:08 GMT" skipped="0" hostname="QiuZidanes-MacBookAir.local" errors="1">
  <testcase name="getClassPathByUri2" time="0.002" classname="file.FileUtilTest"/>
  <testcase name="getClassPathByUri2" time="0.015" classname="file.FileUtilTest"/>
  <testcase name="paramTest1" time="0.003" classname="file.FileUtilTest"/>
  <testcase name="getClassPathByUri1" time="0.002" classname="file.FileUtilTest"/>
  <testcase name="getClassPathByUri1" time="0.007" classname="file.FileUtilTest"/>
  <testcase name="exceptionTest1" time="0.002" classname="file.FileUtilTest">
    <error type="java.lang.IllegalAccessException" message="Nullll">
      <![CDATA[java.lang.IllegalAccessException: Nullll
	at file.FileUtilTest.exceptionTest1(FileUtilTest.java:100)
	at sun.reflect.NativeMethodAccessorImpl.invoke0(Native Method)
	at sun.reflect.NativeMethodAccessorImpl.invoke(NativeMethodAccessorImpl.java:62)
	at sun.reflect.DelegatingMethodAccessorImpl.invoke(DelegatingMethodAccessorImpl.java:43)
	at java.lang.reflect.Method.invoke(Method.java:497)
	at org.testng.internal.MethodInvocationHelper.invokeMethod(MethodInvocationHelper.java:104)
	at org.testng.internal.Invoker.invokeMethod(Invoker.java:645)
	at org.testng.internal.Invoker.invokeTestMethod(Invoker.java:851)
	at org.testng.internal.Invoker.invokeTestMethods(Invoker.java:1177)
	at org.testng.internal.TestMethodWorker.invokeTestMethods(TestMethodWorker.java:129)
	at org.testng.internal.TestMethodWorker.run(TestMethodWorker.java:112)
	at org.testng.TestRunner.privateRun(TestRunner.java:756)
	at org.testng.TestRunner.run(TestRunner.java:610)
	at org.testng.SuiteRunner.runTest(SuiteRunner.java:387)
	at org.testng.SuiteRunner.runSequentially(SuiteRunner.java:382)
	at org.testng.SuiteRunner.privateRun(SuiteRunner.java:340)
	at org.testng.SuiteRunner.run(SuiteRunner.java:289)
	at org.testng.SuiteRunnerWorker.runSuite(SuiteRunnerWorker.java:52)
	at org.testng.SuiteRunnerWorker.run(SuiteRunnerWorker.java:86)
	at org.testng.TestNG.runSuitesSequentially(TestNG.java:1293)
	at org.testng.TestNG.runSuitesLocally(TestNG.java:1218)
	at org.testng.TestNG.runSuites(TestNG.java:1133)
	at org.testng.TestNG.run(TestNG.java:1104)
	at org.testng.remote.AbstractRemoteTestNG.run(AbstractRemoteTestNG.java:132)
	at org.testng.remote.RemoteTestNG.initAndRun(RemoteTestNG.java:236)
	at org.testng.remote.RemoteTestNG.main(RemoteTestNG.java:81)
]]>
    </error>
  </testcase> <!-- exceptionTest1 -->
  <testcase name="getClassPathByUri2" classname="file.FileUtilTest">
    <skipped/>
  </testcase> <!-- getClassPathByUri2 -->
  <testcase name="getClassPathByUri1" classname="file.FileUtilTest">
    <skipped/>
  </testcase> <!-- getClassPathByUri1 -->
  <testcase name="paramTest1" classname="file.FileUtilTest">
    <skipped/>
  </testcase> <!-- paramTest1 -->
  <testcase name="paramTest1" classname="file.FileUtilTest">
    <skipped/>
  </testcase> <!-- paramTest1 -->
  <testcase name="exceptionTest1" classname="file.FileUtilTest">
    <skipped/>
  </testcase> <!-- exceptionTest1 -->
  <testcase name="exceptionTest1" classname="file.FileUtilTest">
    <skipped/>
  </testcase> <!-- exceptionTest1 -->
</testsuite> <!-- file.FileUtilTest -->
